{
    "identifier": "CVE-2019-5729",
    "summary": "Splunk-SDK-Python before 1.6.6 does not properly verify untrusted TLS server certificates, which could result in man-in-the-middle attacks.",
    "references": [
        {
            "url": "",
            "reference_id": "pyup.io-36969"
        }
    ],
    "vulnerable_packages": [
        "pkg:pypi/splunk-sdk@1.0.0",
        "pkg:pypi/splunk-sdk@1.6.2",
        "pkg:pypi/splunk-sdk@0.8.0",
        "pkg:pypi/splunk-sdk@1.3.0",
        "pkg:pypi/splunk-sdk@1.3.1",
        "pkg:pypi/splunk-sdk@1.6.0",
        "pkg:pypi/splunk-sdk@1.6.4",
        "pkg:pypi/splunk-sdk@1.4.0",
        "pkg:pypi/splunk-sdk@0.1.0",
        "pkg:pypi/splunk-sdk@1.6.1",
        "pkg:pypi/splunk-sdk@1.2.3",
        "pkg:pypi/splunk-sdk@1.1.0",
        "pkg:pypi/splunk-sdk@1.5.0",
        "pkg:pypi/splunk-sdk@1.2.0",
        "pkg:pypi/splunk-sdk@1.6.3",
        "pkg:pypi/splunk-sdk@1.6.5",
        "pkg:pypi/splunk-sdk@1.2.2",
        "pkg:pypi/splunk-sdk@1.2.1",
        "pkg:pypi/splunk-sdk@0.1.0a"
    ],
    "resolved_packages": [
        "pkg:pypi/splunk-sdk@1.6.8",
        "pkg:pypi/splunk-sdk@1.6.14",
        "pkg:pypi/splunk-sdk@1.6.7",
        "pkg:pypi/splunk-sdk@1.6.9",
        "pkg:pypi/splunk-sdk@1.6.6",
        "pkg:pypi/splunk-sdk@1.6.10",
        "pkg:pypi/splunk-sdk@1.6.11",
        "pkg:pypi/splunk-sdk@1.6.13",
        "pkg:pypi/splunk-sdk@1.6.12"
    ]
}