{
    "identifier": "VULCODE-2020-09-26 12:48:50.223623",
    "summary": "ldap3 before 0.9.5.4 has several security issues in lazy connections.",
    "references": [
        {
            "url": "",
            "reference_id": "pyup.io-25875"
        }
    ],
    "vulnerable_packages": [],
    "resolved_packages": [
        "pkg:pypi/ldap3@2.8.1",
        "pkg:pypi/ldap3@2.2.0",
        "pkg:pypi/ldap3@2.3",
        "pkg:pypi/ldap3@1.3.3",
        "pkg:pypi/ldap3@1.0.2",
        "pkg:pypi/ldap3@2.5.1",
        "pkg:pypi/ldap3@1.3.1",
        "pkg:pypi/ldap3@1.2.1",
        "pkg:pypi/ldap3@2.5.2",
        "pkg:pypi/ldap3@2.1.1",
        "pkg:pypi/ldap3@2.0.9",
        "pkg:pypi/ldap3@1.0.4",
        "pkg:pypi/ldap3@2.6",
        "pkg:pypi/ldap3@2.8",
        "pkg:pypi/ldap3@1.1.2",
        "pkg:pypi/ldap3@0.9.8.7.post1",
        "pkg:pypi/ldap3@2.7",
        "pkg:pypi/ldap3@2.5",
        "pkg:pypi/ldap3@2.1.0",
        "pkg:pypi/ldap3@2.2.2",
        "pkg:pypi/ldap3@2.4.1",
        "pkg:pypi/ldap3@2.2.4",
        "pkg:pypi/ldap3@1.4.0",
        "pkg:pypi/ldap3@2.6.1",
        "pkg:pypi/ldap3@1.0.3",
        "pkg:pypi/ldap3@2.2.1",
        "pkg:pypi/ldap3@2.2.3",
        "pkg:pypi/ldap3@2.4",
        "pkg:pypi/ldap3@1.2.2"
    ]
}