{
    "identifier": "VULCODE-2020-09-26 12:46:46.139445",
    "summary": "django-initial-avatars before 0.4 has a unspecified security issue and is vulnerable via unknown vectors.",
    "references": [
        {
            "url": "",
            "reference_id": "pyup.io-25767"
        }
    ],
    "vulnerable_packages": [
        "pkg:pypi/django-initial-avatars@0.1",
        "pkg:pypi/django-initial-avatars@0.3.0",
        "pkg:pypi/django-initial-avatars@0.2.1",
        "pkg:pypi/django-initial-avatars@0.2.4",
        "pkg:pypi/django-initial-avatars@0.2.5",
        "pkg:pypi/django-initial-avatars@0.2",
        "pkg:pypi/django-initial-avatars@0.2.2",
        "pkg:pypi/django-initial-avatars@0.3.1",
        "pkg:pypi/django-initial-avatars@0.2.3"
    ],
    "resolved_packages": [
        "pkg:pypi/django-initial-avatars@0.5.2",
        "pkg:pypi/django-initial-avatars@0.9",
        "pkg:pypi/django-initial-avatars@0.7",
        "pkg:pypi/django-initial-avatars@0.7.5",
        "pkg:pypi/django-initial-avatars@0.4.0",
        "pkg:pypi/django-initial-avatars@0.7.3",
        "pkg:pypi/django-initial-avatars@0.5.0",
        "pkg:pypi/django-initial-avatars@0.7.2",
        "pkg:pypi/django-initial-avatars@0.9.1",
        "pkg:pypi/django-initial-avatars@0.7.1",
        "pkg:pypi/django-initial-avatars@0.8.1",
        "pkg:pypi/django-initial-avatars@0.5.1",
        "pkg:pypi/django-initial-avatars@0.6",
        "pkg:pypi/django-initial-avatars@0.7.4"
    ]
}