{
    "identifier": "VULCODE-2020-09-26 12:44:46.387087",
    "summary": "bigchaindb-driver before 0.5.2 used an unsecure version of `cryptoconditions` - CVE-2018-10903",
    "references": [
        {
            "url": "",
            "reference_id": "pyup.io-36427"
        }
    ],
    "vulnerable_packages": [
        "pkg:pypi/bigchaindb-driver@0.3.0",
        "pkg:pypi/bigchaindb-driver@0.0.2.dev10",
        "pkg:pypi/bigchaindb-driver@0.5.0",
        "pkg:pypi/bigchaindb-driver@0.0.2",
        "pkg:pypi/bigchaindb-driver@0.1.2",
        "pkg:pypi/bigchaindb-driver@0.0.1.dev1",
        "pkg:pypi/bigchaindb-driver@0.4.0",
        "pkg:pypi/bigchaindb-driver@0.2.2",
        "pkg:pypi/bigchaindb-driver@0.2.0",
        "pkg:pypi/bigchaindb-driver@0.0.2.dev5",
        "pkg:pypi/bigchaindb-driver@0.0.3",
        "pkg:pypi/bigchaindb-driver@0.2.1",
        "pkg:pypi/bigchaindb-driver@0.0.2.dev2",
        "pkg:pypi/bigchaindb-driver@0.1.0",
        "pkg:pypi/bigchaindb-driver@0.1.3",
        "pkg:pypi/bigchaindb-driver@0.0.2.dev3",
        "pkg:pypi/bigchaindb-driver@0.0.1a1",
        "pkg:pypi/bigchaindb-driver@0.0.2.dev8",
        "pkg:pypi/bigchaindb-driver@0.0.2.dev11",
        "pkg:pypi/bigchaindb-driver@0.3.1",
        "pkg:pypi/bigchaindb-driver@0.4.1",
        "pkg:pypi/bigchaindb-driver@0.5.0a4",
        "pkg:pypi/bigchaindb-driver@0.0.2.dev6",
        "pkg:pypi/bigchaindb-driver@0.0.2.dev1",
        "pkg:pypi/bigchaindb-driver@0.0.2.dev4",
        "pkg:pypi/bigchaindb-driver@0.5.1",
        "pkg:pypi/bigchaindb-driver@0.0.2.dev12",
        "pkg:pypi/bigchaindb-driver@0.5.0a1",
        "pkg:pypi/bigchaindb-driver@0.0.2.dev9",
        "pkg:pypi/bigchaindb-driver@0.5.0a2",
        "pkg:pypi/bigchaindb-driver@0.0.2.dev7"
    ],
    "resolved_packages": [
        "pkg:pypi/bigchaindb-driver@0.6.2",
        "pkg:pypi/bigchaindb-driver@0.6.1",
        "pkg:pypi/bigchaindb-driver@0.5.2",
        "pkg:pypi/bigchaindb-driver@0.6.0",
        "pkg:pypi/bigchaindb-driver@0.5.3"
    ]
}