{
    "identifier": "VULCODE-2020-09-26 12:46:52.917842",
    "summary": "django-rated before 1.1.2 has a unspecified security issue and is vulnerable via unknown vectors.",
    "references": [
        {
            "url": "",
            "reference_id": "pyup.io-25781"
        }
    ],
    "vulnerable_packages": [
        "pkg:pypi/django-rated@0.0.2",
        "pkg:pypi/django-rated@1.1.0",
        "pkg:pypi/django-rated@0.0.1",
        "pkg:pypi/django-rated@1.0.1",
        "pkg:pypi/django-rated@1.0.3",
        "pkg:pypi/django-rated@1.0.0",
        "pkg:pypi/django-rated@1.0.2",
        "pkg:pypi/django-rated@1.1.1",
        "pkg:pypi/django-rated@0.0.3"
    ],
    "resolved_packages": [
        "pkg:pypi/django-rated@1.1.2"
    ]
}