{
    "identifier": "VULCODE-2020-09-26 12:46:36.530174",
    "summary": "django-ca before 1.9.0 did not properly escape x509 extensions, allowing for potential injection attacks.",
    "references": [
        {
            "url": "",
            "reference_id": "pyup.io-36405"
        }
    ],
    "vulnerable_packages": [
        "pkg:pypi/django-ca@1.6.2",
        "pkg:pypi/django-ca@1.6.0",
        "pkg:pypi/django-ca@1.5.1",
        "pkg:pypi/django-ca@1.4.0",
        "pkg:pypi/django-ca@1.1.1",
        "pkg:pypi/django-ca@1.0.0b2",
        "pkg:pypi/django-ca@1.2.2",
        "pkg:pypi/django-ca@1.6.3",
        "pkg:pypi/django-ca@1.0.0",
        "pkg:pypi/django-ca@1.0.0b1",
        "pkg:pypi/django-ca@1.3.0",
        "pkg:pypi/django-ca@1.2.1",
        "pkg:pypi/django-ca@1.1.0",
        "pkg:pypi/django-ca@1.0.1",
        "pkg:pypi/django-ca@1.7.0",
        "pkg:pypi/django-ca@1.2.0",
        "pkg:pypi/django-ca@1.6.1",
        "pkg:pypi/django-ca@1.0.0a1",
        "pkg:pypi/django-ca@1.5.0",
        "pkg:pypi/django-ca@1.4.1"
    ],
    "resolved_packages": [
        "pkg:pypi/django-ca@1.16.1",
        "pkg:pypi/django-ca@1.13.0",
        "pkg:pypi/django-ca@1.9.0",
        "pkg:pypi/django-ca@1.16.0",
        "pkg:pypi/django-ca@1.10.0",
        "pkg:pypi/django-ca@1.11.0",
        "pkg:pypi/django-ca@1.15.0",
        "pkg:pypi/django-ca@1.14.0",
        "pkg:pypi/django-ca@1.12.0"
    ]
}